[2024-05-04T07:18:13.412+0000] {taskinstance.py:1159} INFO - Dependencies all met for dep_context=non-requeueable deps ti=<TaskInstance: main.write_to_clean_data scheduled__2023-03-04T00:00:00+00:00 [queued]>
[2024-05-04T07:18:13.417+0000] {taskinstance.py:1159} INFO - Dependencies all met for dep_context=requeueable deps ti=<TaskInstance: main.write_to_clean_data scheduled__2023-03-04T00:00:00+00:00 [queued]>
[2024-05-04T07:18:13.418+0000] {taskinstance.py:1361} INFO - Starting attempt 1 of 2
[2024-05-04T07:18:13.424+0000] {taskinstance.py:1382} INFO - Executing <Task(PythonOperator): write_to_clean_data> on 2023-03-04 00:00:00+00:00
[2024-05-04T07:18:13.434+0000] {standard_task_runner.py:57} INFO - Started process 1730 to run task
[2024-05-04T07:18:13.438+0000] {standard_task_runner.py:84} INFO - Running: ['***', 'tasks', 'run', 'main', 'write_to_clean_data', 'scheduled__2023-03-04T00:00:00+00:00', '--job-id', '6', '--raw', '--subdir', 'DAGS_FOLDER/main.py', '--cfg-path', '/tmp/tmpd2zdo89q']
[2024-05-04T07:18:13.441+0000] {standard_task_runner.py:85} INFO - Job 6: Subtask write_to_clean_data
[2024-05-04T07:18:13.507+0000] {task_command.py:415} INFO - Running <TaskInstance: main.write_to_clean_data scheduled__2023-03-04T00:00:00+00:00 [running]> on host cc8c6d1ef843
[2024-05-04T07:18:13.560+0000] {taskinstance.py:1660} INFO - Exporting env vars: AIRFLOW_CTX_DAG_OWNER='***' AIRFLOW_CTX_DAG_ID='main' AIRFLOW_CTX_TASK_ID='write_to_clean_data' AIRFLOW_CTX_EXECUTION_DATE='2023-03-04T00:00:00+00:00' AIRFLOW_CTX_TRY_NUMBER='1' AIRFLOW_CTX_DAG_RUN_ID='scheduled__2023-03-04T00:00:00+00:00'
[2024-05-04T07:18:13.657+0000] {warnings.py:109} WARNING - /opt/***/dags/main.py:60: UserWarning: pandas only supports SQLAlchemy connectable (engine/connection) or database string URI or sqlite3 DBAPI2 connection. Other DBAPI2 objects are not tested. Please consider using SQLAlchemy.
  df = pd.read_sql_query(query, conn)

[2024-05-04T07:18:21.367+0000] {taskinstance.py:1943} ERROR - Task failed with exception
Traceback (most recent call last):
  File "/home/airflow/.local/lib/python3.8/site-packages/airflow/operators/python.py", line 192, in execute
    return_value = self.execute_callable()
  File "/home/airflow/.local/lib/python3.8/site-packages/airflow/operators/python.py", line 209, in execute_callable
    return self.python_callable(*self.op_args, **self.op_kwargs)
  File "/opt/airflow/dags/main.py", line 75, in write_to_clean_data
    df.to_sql('clean_data', con=engine, if_exists='replace', index=False)
  File "/home/airflow/.local/lib/python3.8/site-packages/pandas/core/generic.py", line 2878, in to_sql
    return sql.to_sql(
  File "/home/airflow/.local/lib/python3.8/site-packages/pandas/io/sql.py", line 769, in to_sql
    return pandas_sql.to_sql(
  File "/home/airflow/.local/lib/python3.8/site-packages/pandas/io/sql.py", line 1548, in __exit__
    self.exit_stack.close()
  File "/usr/local/lib/python3.8/contextlib.py", line 533, in close
    self.__exit__(None, None, None)
  File "/usr/local/lib/python3.8/contextlib.py", line 525, in __exit__
    raise exc_details[1]
  File "/usr/local/lib/python3.8/contextlib.py", line 510, in __exit__
    if cb(*exc_details):
  File "/home/airflow/.local/lib/python3.8/site-packages/sqlalchemy/engine/util.py", line 237, in __exit__
    self.rollback()
  File "/home/airflow/.local/lib/python3.8/site-packages/sqlalchemy/util/langhelpers.py", line 70, in __exit__
    compat.raise_(
  File "/home/airflow/.local/lib/python3.8/site-packages/sqlalchemy/util/compat.py", line 211, in raise_
    raise exception
  File "/home/airflow/.local/lib/python3.8/site-packages/sqlalchemy/engine/util.py", line 233, in __exit__
    self.commit()
  File "/home/airflow/.local/lib/python3.8/site-packages/sqlalchemy/engine/base.py", line 2469, in commit
    self._do_commit()
  File "/home/airflow/.local/lib/python3.8/site-packages/sqlalchemy/engine/base.py", line 2659, in _do_commit
    self._connection_commit_impl()
  File "/home/airflow/.local/lib/python3.8/site-packages/sqlalchemy/engine/base.py", line 2630, in _connection_commit_impl
    self.connection._commit_impl()
  File "/home/airflow/.local/lib/python3.8/site-packages/sqlalchemy/engine/base.py", line 1096, in _commit_impl
    self._handle_dbapi_exception(e, None, None, None, None)
  File "/home/airflow/.local/lib/python3.8/site-packages/sqlalchemy/engine/base.py", line 2138, in _handle_dbapi_exception
    util.raise_(exc_info[1], with_traceback=exc_info[2])
  File "/home/airflow/.local/lib/python3.8/site-packages/sqlalchemy/util/compat.py", line 211, in raise_
    raise exception
  File "/home/airflow/.local/lib/python3.8/site-packages/sqlalchemy/engine/base.py", line 1094, in _commit_impl
    self.engine.dialect.do_commit(self.connection)
  File "/home/airflow/.local/lib/python3.8/site-packages/sqlalchemy/engine/base.py", line 537, in connection
    return self._revalidate_connection()
  File "/home/airflow/.local/lib/python3.8/site-packages/sqlalchemy/engine/base.py", line 650, in _revalidate_connection
    self._invalid_transaction()
  File "/home/airflow/.local/lib/python3.8/site-packages/sqlalchemy/engine/base.py", line 622, in _invalid_transaction
    raise exc.PendingRollbackError(
sqlalchemy.exc.PendingRollbackError: Can't reconnect until invalid transaction is rolled back. (Background on this error at: https://sqlalche.me/e/14/8s2b)
[2024-05-04T07:18:21.452+0000] {taskinstance.py:1400} INFO - Marking task as UP_FOR_RETRY. dag_id=main, task_id=write_to_clean_data, execution_date=20230304T000000, start_date=20240504T071813, end_date=20240504T071821
[2024-05-04T07:18:21.510+0000] {standard_task_runner.py:104} ERROR - Failed to execute job 6 for task write_to_clean_data (Can't reconnect until invalid transaction is rolled back. (Background on this error at: https://sqlalche.me/e/14/8s2b); 1730)
[2024-05-04T07:18:21.617+0000] {local_task_job_runner.py:228} INFO - Task exited with return code 1
[2024-05-04T07:18:21.662+0000] {taskinstance.py:2784} INFO - 0 downstream tasks scheduled from follow-on schedule check
