[2024-05-04T16:53:55.941+0000] {taskinstance.py:1159} INFO - Dependencies all met for dep_context=non-requeueable deps ti=<TaskInstance: main.write_to_raw_data_task manual__2024-05-04T16:53:53.417803+00:00 [queued]>
[2024-05-04T16:53:55.947+0000] {taskinstance.py:1159} INFO - Dependencies all met for dep_context=requeueable deps ti=<TaskInstance: main.write_to_raw_data_task manual__2024-05-04T16:53:53.417803+00:00 [queued]>
[2024-05-04T16:53:55.947+0000] {taskinstance.py:1361} INFO - Starting attempt 1 of 2
[2024-05-04T16:53:55.955+0000] {taskinstance.py:1382} INFO - Executing <Task(PythonOperator): write_to_raw_data_task> on 2024-05-04 16:53:53.417803+00:00
[2024-05-04T16:53:55.962+0000] {standard_task_runner.py:57} INFO - Started process 74 to run task
[2024-05-04T16:53:55.967+0000] {standard_task_runner.py:84} INFO - Running: ['***', 'tasks', 'run', 'main', 'write_to_raw_data_task', 'manual__2024-05-04T16:53:53.417803+00:00', '--job-id', '80', '--raw', '--subdir', 'DAGS_FOLDER/main.py', '--cfg-path', '/tmp/tmpf_cw3g56']
[2024-05-04T16:53:55.971+0000] {standard_task_runner.py:85} INFO - Job 80: Subtask write_to_raw_data_task
[2024-05-04T16:53:56.016+0000] {task_command.py:415} INFO - Running <TaskInstance: main.write_to_raw_data_task manual__2024-05-04T16:53:53.417803+00:00 [running]> on host 243a4ba842c9
[2024-05-04T16:53:56.081+0000] {taskinstance.py:1660} INFO - Exporting env vars: AIRFLOW_CTX_DAG_OWNER='***' AIRFLOW_CTX_DAG_ID='main' AIRFLOW_CTX_TASK_ID='write_to_raw_data_task' AIRFLOW_CTX_EXECUTION_DATE='2024-05-04T16:53:53.417803+00:00' AIRFLOW_CTX_TRY_NUMBER='1' AIRFLOW_CTX_DAG_RUN_ID='manual__2024-05-04T16:53:53.417803+00:00'
[2024-05-04T16:54:06.392+0000] {taskinstance.py:1943} ERROR - Task failed with exception
Traceback (most recent call last):
  File "/home/airflow/.local/lib/python3.8/site-packages/urllib3/connectionpool.py", line 714, in urlopen
    httplib_response = self._make_request(
  File "/home/airflow/.local/lib/python3.8/site-packages/urllib3/connectionpool.py", line 403, in _make_request
    self._validate_conn(conn)
  File "/home/airflow/.local/lib/python3.8/site-packages/urllib3/connectionpool.py", line 1053, in _validate_conn
    conn.connect()
  File "/home/airflow/.local/lib/python3.8/site-packages/urllib3/connection.py", line 419, in connect
    self.sock = ssl_wrap_socket(
  File "/home/airflow/.local/lib/python3.8/site-packages/urllib3/util/ssl_.py", line 449, in ssl_wrap_socket
    ssl_sock = _ssl_wrap_socket_impl(
  File "/home/airflow/.local/lib/python3.8/site-packages/urllib3/util/ssl_.py", line 493, in _ssl_wrap_socket_impl
    return ssl_context.wrap_socket(sock, server_hostname=server_hostname)
  File "/usr/local/lib/python3.8/ssl.py", line 500, in wrap_socket
    return self.sslsocket_class._create(
  File "/usr/local/lib/python3.8/ssl.py", line 1040, in _create
    self.do_handshake()
  File "/usr/local/lib/python3.8/ssl.py", line 1309, in do_handshake
    self._sslobj.do_handshake()
ssl.SSLEOFError: EOF occurred in violation of protocol (_ssl.c:1131)

During handling of the above exception, another exception occurred:

Traceback (most recent call last):
  File "/home/airflow/.local/lib/python3.8/site-packages/requests/adapters.py", line 486, in send
    resp = conn.urlopen(
  File "/home/airflow/.local/lib/python3.8/site-packages/urllib3/connectionpool.py", line 798, in urlopen
    retries = retries.increment(
  File "/home/airflow/.local/lib/python3.8/site-packages/urllib3/util/retry.py", line 592, in increment
    raise MaxRetryError(_pool, url, error or ResponseError(cause))
urllib3.exceptions.MaxRetryError: HTTPSConnectionPool(host='drive.usercontent.google.com', port=443): Max retries exceeded with url: /download?id=1k5-1caezQ3zWJbKaiMULTGq-3sz6uThC&export=download (Caused by SSLError(SSLEOFError(8, 'EOF occurred in violation of protocol (_ssl.c:1131)')))

During handling of the above exception, another exception occurred:

Traceback (most recent call last):
  File "/home/airflow/.local/lib/python3.8/site-packages/airflow/operators/python.py", line 192, in execute
    return_value = self.execute_callable()
  File "/home/airflow/.local/lib/python3.8/site-packages/airflow/operators/python.py", line 209, in execute_callable
    return self.python_callable(*self.op_args, **self.op_kwargs)
  File "/opt/airflow/dags/main.py", line 15, in write_to_raw_data
    response = requests.get(link)
  File "/home/airflow/.local/lib/python3.8/site-packages/requests/api.py", line 73, in get
    return request("get", url, params=params, **kwargs)
  File "/home/airflow/.local/lib/python3.8/site-packages/requests/api.py", line 59, in request
    return session.request(method=method, url=url, **kwargs)
  File "/home/airflow/.local/lib/python3.8/site-packages/requests/sessions.py", line 589, in request
    resp = self.send(prep, **send_kwargs)
  File "/home/airflow/.local/lib/python3.8/site-packages/requests/sessions.py", line 725, in send
    history = [resp for resp in gen]
  File "/home/airflow/.local/lib/python3.8/site-packages/requests/sessions.py", line 725, in <listcomp>
    history = [resp for resp in gen]
  File "/home/airflow/.local/lib/python3.8/site-packages/requests/sessions.py", line 266, in resolve_redirects
    resp = self.send(
  File "/home/airflow/.local/lib/python3.8/site-packages/requests/sessions.py", line 703, in send
    r = adapter.send(request, **kwargs)
  File "/home/airflow/.local/lib/python3.8/site-packages/requests/adapters.py", line 517, in send
    raise SSLError(e, request=request)
requests.exceptions.SSLError: HTTPSConnectionPool(host='drive.usercontent.google.com', port=443): Max retries exceeded with url: /download?id=1k5-1caezQ3zWJbKaiMULTGq-3sz6uThC&export=download (Caused by SSLError(SSLEOFError(8, 'EOF occurred in violation of protocol (_ssl.c:1131)')))
[2024-05-04T16:54:06.406+0000] {taskinstance.py:1400} INFO - Marking task as UP_FOR_RETRY. dag_id=main, task_id=write_to_raw_data_task, execution_date=20240504T165353, start_date=20240504T165355, end_date=20240504T165406
[2024-05-04T16:54:06.418+0000] {standard_task_runner.py:104} ERROR - Failed to execute job 80 for task write_to_raw_data_task (HTTPSConnectionPool(host='drive.usercontent.google.com', port=443): Max retries exceeded with url: /download?id=1k5-1caezQ3zWJbKaiMULTGq-3sz6uThC&export=download (Caused by SSLError(SSLEOFError(8, 'EOF occurred in violation of protocol (_ssl.c:1131)'))); 74)
[2024-05-04T16:54:06.441+0000] {local_task_job_runner.py:228} INFO - Task exited with return code 1
[2024-05-04T16:54:06.460+0000] {taskinstance.py:2784} INFO - 0 downstream tasks scheduled from follow-on schedule check
